<?xml version="1.0" ?>
<sdf version="1.9">
  <model name="standard_vtol">
    <pose>0 0 0.25 0 0 0</pose>

    <link name='base_link'>
      <pose>0 0 0 0 0 0</pose>
      <inertial>
        <pose>0 0 0 0 0 0</pose>
        <mass>2.8</mass>
        <inertia>
          <ixx>0.085</ixx>
          <ixy>0</ixy>
          <ixz>0</ixz>
          <iyy>0.065</iyy>
          <iyz>0</iyz>
          <izz>0.140</izz>
        </inertia>
      </inertial>
      <collision name='base_link_collision'>
        <pose>0 0 0 0 0 0</pose>
        <geometry>
          <box>
            <size>0.70 1.13 0.12</size>
          </box>
        </geometry>
      </collision>
      <visual name='base_link_visual'>
        <pose>0 0 0 0 0 0</pose>
        <geometry>
          <mesh>
            <scale>0.52 0.52 0.52</scale>
            <uri>model://standard_vtol/meshes/x8_wing.dae</uri>
          </mesh>
        </geometry>
        <material>
          <ambient>0.1 0.1 0.1 1</ambient>
          <diffuse>0.1 0.1 0.1 1</diffuse>
          <specular>0.5 0.5 0.5 1</specular> 
        </material>
      </visual>
    </link>

    <plugin filename="gz-sim-lift-drag-system" name="gz::sim::systems::LiftDrag">
      <a0>0.13</a0>
      <cla>3.7</cla>
      <cda>0.06</cda>
      <area>0.31</area>
      <air_density>1.2041</air_density>
      <forward>1 0 0</forward>
      <upward>0 0 1</upward>
      <link_name>base_link</link_name>
    </plugin>

    <link name="left_elevon">
      <inertial>
        <mass>0.05</mass>
        <inertia>
          <ixx>0.0001</ixx>
          <iyy>0.0001</iyy>
          <izz>0.0001</izz>
        </inertia>
      </inertial>
      <visual name='left_elevon_visual'>
        <geometry>
          <mesh>
            <scale>0.52 0.52 0.52</scale>
            <uri>model://standard_vtol/meshes/x8_elevon_left.dae</uri>
          </mesh>
        </geometry>
        <material>
          <ambient>0 0 1 1</ambient>
          <diffuse>0 0 1 1</diffuse>
          <specular>0.1 0.1 0.1 1</specular>
        </material>
      </visual>
    </link>

    <joint name='left_elevon_joint' type='revolute'>
      <parent>base_link</parent>
      <child>left_elevon</child>
      <pose>-0.25 0.40 0 0 0 0</pose>
      <axis>
        <xyz>0 1 0</xyz>
        <limit>
          <lower>-0.53</lower>
          <upper>0.53</upper>
        </limit>
      </axis>
    </joint>

    <plugin filename="gz-sim-lift-drag-system" name="gz::sim::systems::LiftDrag">
      <a0>0.15</a0>
      <cla>6.8</cla>
      <cda>0.06</cda>
      <area>0.04</area>
      <air_density>1.2041</air_density>
      <forward>1 0 0</forward>
      <upward>0 0 1</upward>
      <link_name>base_link</link_name>
      <control_joint_name>left_elevon_joint</control_joint_name>
      <control_joint_rad_to_cl>-4.0</control_joint_rad_to_cl>
    </plugin>

    <link name="right_elevon">
      <inertial>
        <mass>0.05</mass>
        <inertia>
          <ixx>0.0001</ixx>
          <iyy>0.0001</iyy>
          <izz>0.0001</izz>
        </inertia>
      </inertial>
      <visual name='right_elevon_visual'>
        <geometry>
          <mesh>
            <scale>0.52 0.52 0.52</scale>
            <uri>model://standard_vtol/meshes/x8_elevon_right.dae</uri>
          </mesh>
        </geometry>
        <material>
          <ambient>0 0 1 1</ambient>
          <diffuse>0 0 1 1</diffuse>
          <specular>0.1 0.1 0.1 1</specular>
        </material>
      </visual>
    </link>

    <joint name='right_elevon_joint' type='revolute'>
      <parent>base_link</parent>
      <child>right_elevon</child>
      <pose>-0.25 -0.40 0 0 0 0</pose>
      <axis>
        <xyz>0 1 0</xyz>
        <limit>
          <lower>-0.53</lower>
          <upper>0.53</upper>
        </limit>
      </axis>
    </joint>

    <plugin filename="gz-sim-lift-drag-system" name="gz::sim::systems::LiftDrag">
      <a0>0.15</a0>
      <cla>6.8</cla>
      <cda>0.06</cda>
      <area>0.04</area>
      <air_density>1.2041</air_density>
      <forward>1 0 0</forward>
      <upward>0 0 1</upward>
      <link_name>base_link</link_name>
      <control_joint_name>right_elevon_joint</control_joint_name>
      <control_joint_rad_to_cl>-4.0</control_joint_rad_to_cl>
    </plugin>

    <link name='rotor_0'>
      <pose>0.25 -0.35 0.05 0 0 0</pose>
      <inertial>
        <mass>0.04</mass>
        <inertia>
          <ixx>5e-5</ixx>
          <iyy>5e-5</iyy>
          <izz>5e-5</izz>
        </inertia>
      </inertial>
      <visual name='rotor_0_visual'>
        <geometry>
          <mesh>
            <scale>0.7 0.7 0.7</scale>
            <uri>model://standard_vtol/meshes/iris_prop_ccw.dae</uri>
          </mesh>
        </geometry>
        <material>
          <ambient>0 0 1 1</ambient>
          <diffuse>0 0 1 1</diffuse>
        </material>
      </visual>
    </link>

    <joint name='rotor_0_joint' type='revolute'>
      <child>rotor_0</child>
      <parent>base_link</parent>
      <axis>
        <xyz>0 0 1</xyz>
        <limit>
          <lower>-1e16</lower>
          <upper>1e16</upper>
        </limit>
      </axis>
    </joint>

    <plugin filename="gz-sim-lift-drag-system" name="gz::sim::systems::LiftDrag">
      <a0>0.3</a0>
      <cla>4.25</cla>
      <cda>0.10</cda>
      <area>0.0015</area>
      <cp>0.05 0 0</cp>
      <air_density>1.2041</air_density>
      <forward>0 1 0</forward>
      <upward>0 0 1</upward>
      <link_name>rotor_0</link_name>
    </plugin>

    <link name='rotor_1'>
      <pose>-0.25 0.35 0.05 0 0 0</pose>
      <inertial>
        <mass>0.04</mass>
        <inertia>
          <ixx>5e-5</ixx>
          <iyy>5e-5</iyy>
          <izz>5e-5</izz>
        </inertia>
      </inertial>
      <visual name='rotor_1_visual'>
        <geometry>
          <mesh>
            <scale>0.7 0.7 0.7</scale>
            <uri>model://standard_vtol/meshes/iris_prop_ccw.dae</uri>
          </mesh>
        </geometry>
        <material>
          <ambient>0 0 1 1</ambient>
          <diffuse>0 0 1 1</diffuse>
        </material>
      </visual>
    </link>

    <joint name='rotor_1_joint' type='revolute'>
      <child>rotor_1</child>
      <parent>base_link</parent>
      <axis>
        <xyz>0 0 1</xyz>
      </axis>
    </joint>

    <plugin filename="gz-sim-lift-drag-system" name="gz::sim::systems::LiftDrag">
      <a0>0.3</a0>
      <cla>4.25</cla>
      <cda>0.10</cda>
      <area>0.0015</area>
      <cp>0.05 0 0</cp>
      <air_density>1.2041</air_density>
      <forward>0 1 0</forward>
      <upward>0 0 1</upward>
      <link_name>rotor_1</link_name>
    </plugin>

    <link name='rotor_2'>
      <pose>0.25 0.35 0.05 0 0 0</pose>
      <inertial>
        <mass>0.04</mass>
        <inertia>
          <ixx>5e-5</ixx>
          <iyy>5e-5</iyy>
          <izz>5e-5</izz>
        </inertia>
      </inertial>
      <visual name='rotor_2_visual'>
        <geometry>
          <mesh>
            <scale>0.7 0.7 0.7</scale>
            <uri>model://standard_vtol/meshes/iris_prop_cw.dae</uri>
          </mesh>
        </geometry>
        <material>
          <ambient>0 0 1 1</ambient>
          <diffuse>0 0 1 1</diffuse>
        </material>
      </visual>
    </link>

    <joint name='rotor_2_joint' type='revolute'>
      <child>rotor_2</child>
      <parent>base_link</parent>
      <axis>
        <xyz>0 0 1</xyz>
      </axis>
    </joint>

    <plugin filename="gz-sim-lift-drag-system" name="gz::sim::systems::LiftDrag">
      <a0>0.3</a0>
      <cla>4.25</cla>
      <cda>0.10</cda>
      <area>0.0015</area>
      <cp>-0.05 0 0</cp>
      <air_density>1.2041</air_density>
      <forward>0 -1 0</forward>
      <upward>0 0 1</upward>
      <link_name>rotor_2</link_name>
    </plugin>

    <link name='rotor_3'>
      <pose>-0.25 -0.35 0.05 0 0 0</pose>
      <inertial>
        <mass>0.04</mass>
        <inertia>
          <ixx>5e-5</ixx>
          <iyy>5e-5</iyy>
          <izz>5e-5</izz>
        </inertia>
      </inertial>
      <visual name='rotor_3_visual'>
        <geometry>
          <mesh>
            <scale>0.7 0.7 0.7</scale>
            <uri>model://standard_vtol/meshes/iris_prop_cw.dae</uri>
          </mesh>
        </geometry>
        <material>
          <ambient>0 0 1 1</ambient>
          <diffuse>0 0 1 1</diffuse>
        </material>
      </visual>
    </link>

    <joint name='rotor_3_joint' type='revolute'>
      <child>rotor_3</child>
      <parent>base_link</parent>
      <axis>
        <xyz>0 0 1</xyz>
      </axis>
    </joint>

    <plugin filename="gz-sim-lift-drag-system" name="gz::sim::systems::LiftDrag">
      <a0>0.3</a0>
      <cla>4.25</cla>
      <cda>0.10</cda>
      <area>0.0015</area>
      <cp>-0.05 0 0</cp>
      <air_density>1.2041</air_density>
      <forward>0 -1 0</forward>
      <upward>0 0 1</upward>
      <link_name>rotor_3</link_name>
    </plugin>

    <link name='rotor_pusher'>
      <pose>-0.30 0 0 0 1.57 0</pose>
      <inertial>
        <mass>0.06</mass>
        <inertia>
          <ixx>8e-5</ixx>
          <iyy>8e-5</iyy>
          <izz>8e-5</izz>
        </inertia>
      </inertial>
      <visual name='visual'>
        <geometry>
          <mesh>
            <scale>1.0 1.0 1.0</scale>
            <uri>model://standard_vtol/meshes/iris_prop_ccw.dae</uri>
          </mesh>
        </geometry>
        <material>
          <ambient>0 0 1 1</ambient>
          <diffuse>0 0 1 1</diffuse>
        </material>
      </visual>
    </link>

    <joint name='rotor_pusher_joint' type='revolute'>
      <child>rotor_pusher</child>
      <parent>base_link</parent>
      <axis>
        <xyz>0 0 1</xyz>
      </axis>
    </joint>

    <plugin filename="gz-sim-lift-drag-system" name="gz::sim::systems::LiftDrag">
      <a0>0.3</a0>
      <cla>4.25</cla>
      <cda>0.10</cda>
      <area>0.02</area>
      <cp>0.08 0 0</cp>
      <air_density>1.2041</air_density>
      <forward>0 1 0</forward>
      <upward>0 0 1</upward>
      <link_name>rotor_pusher</link_name>
    </plugin>

    <link name='imu_link'>
      <inertial>
        <mass>0.1</mass>
        <inertia>
          <ixx>0.0001</ixx>
          <iyy>0.0001</iyy>
          <izz>0.0001</izz>
        </inertia>
      </inertial>
      <sensor name="imu_sensor" type="imu">
        <pose>0 0 0 3.141593 0 0</pose>
        <always_on>1</always_on>
        <update_rate>1000.0</update_rate>
        <imu>
          <angular_velocity>
            <x>
              <noise type="gaussian">
                <mean>0</mean>
                <stddev>0.0002</stddev>
              </noise>
            </x>
            <y>
              <noise type="gaussian">
                <mean>0</mean>
                <stddev>0.0002</stddev>
              </noise>
            </y>
            <z>
              <noise type="gaussian">
                <mean>0</mean>
                <stddev>0.0002</stddev>
              </noise>
            </z>
          </angular_velocity>
          <linear_acceleration>
            <x>
              <noise type="gaussian">
                <mean>0</mean>
                <stddev>0.017</stddev>
              </noise>
            </x>
            <y>
              <noise type="gaussian">
                <mean>0</mean>
                <stddev>0.017</stddev>
              </noise>
            </y>
            <z>
              <noise type="gaussian">
                <mean>0</mean>
                <stddev>0.017</stddev>
              </noise>
            </z>
          </linear_acceleration>
        </imu>
      </sensor>
    </link>

    <joint name='imu_joint' type='revolute'>
      <child>imu_link</child>
      <parent>base_link</parent>
      <axis>
        <xyz>0 0 1</xyz>
        <limit>
          <lower>0</lower>
          <upper>0</upper>
        </limit>
      </axis>
    </joint>

    <plugin filename="gz-sim-joint-state-publisher-system" name="gz::sim::systems::JointStatePublisher">
    </plugin>

    <plugin filename="gz-sim-linear-battery-system" name="gz::sim::systems::LinearBatteryPlugin">
      <battery_name>linear_battery</battery_name>
      <voltage>15.2</voltage>
      <open_circuit_voltage_constant_coef>16.8</open_circuit_voltage_constant_coef>
      <open_circuit_voltage_linear_coef>-2.0</open_circuit_voltage_linear_coef>
      <capacity>6.0</capacity>
      <power_load>50.0</power_load>
    </plugin>

    <plugin filename="gz-sim-apply-joint-force-system" name="gz::sim::systems::ApplyJointForce">
      <joint_name>rotor_0_joint</joint_name>
    </plugin>

    <plugin filename="gz-sim-apply-joint-force-system" name="gz::sim::systems::ApplyJointForce">
      <joint_name>rotor_1_joint</joint_name>
    </plugin>

    <plugin filename="gz-sim-apply-joint-force-system" name="gz::sim::systems::ApplyJointForce">
      <joint_name>rotor_2_joint</joint_name>
    </plugin>

    <plugin filename="gz-sim-apply-joint-force-system" name="gz::sim::systems::ApplyJointForce">
      <joint_name>rotor_3_joint</joint_name>
    </plugin>

    <plugin filename="gz-sim-apply-joint-force-system" name="gz::sim::systems::ApplyJointForce">
      <joint_name>rotor_pusher_joint</joint_name>
    </plugin>

    <plugin filename="gz-sim-apply-joint-force-system" name="gz::sim::systems::ApplyJointForce">
      <joint_name>left_elevon_joint</joint_name>
    </plugin>

    <plugin filename="gz-sim-apply-joint-force-system" name="gz::sim::systems::ApplyJointForce">
      <joint_name>right_elevon_joint</joint_name>
    </plugin>

    <plugin name="ArduPilotPlugin" filename="ArduPilotPlugin">
      <fdm_addr>127.0.0.1</fdm_addr>
      <fdm_port_in>9002</fdm_port_in>
      <connectionTimeoutMaxCount>5</connectionTimeoutMaxCount>
      <lock_step>1</lock_step>
      <modelXYZToAirplaneXForwardZDown degrees="true">0 0 0 180 0 0</modelXYZToAirplaneXForwardZDown>
      <gazeboXYZToNED degrees="true">0 0 0 180 0 90</gazeboXYZToNED>
      <imuName>imu_sensor</imuName>

      <control channel="2">
        <jointName>rotor_pusher_joint</jointName>
        <useForce>1</useForce>
        <multiplier>2200</multiplier>
        <offset>0</offset>
        <servo_min>1000</servo_min>
        <servo_max>2000</servo_max>
        <type>VELOCITY</type>
        <p_gain>0.20</p_gain>
        <cmd_max>20.0</cmd_max>
        <cmd_min>-20.0</cmd_min>
      </control>

      <control channel="0">
        <jointName>left_elevon_joint</jointName>
        <useForce>1</useForce>
        <multiplier>1.0</multiplier>
        <offset>-0.5</offset>
        <servo_min>1000</servo_min>
        <servo_max>2000</servo_max>
        <type>POSITION</type>
        <p_gain>10.0</p_gain>
      </control>

      <control channel="1">
        <jointName>right_elevon_joint</jointName>
        <useForce>1</useForce>
        <multiplier>1.0</multiplier>
        <offset>-0.5</offset>
        <servo_min>1000</servo_min>
        <servo_max>2000</servo_max>
        <type>POSITION</type>
        <p_gain>10.0</p_gain>
      </control>

      <control channel="4">
        <jointName>rotor_0_joint</jointName>
        <useForce>1</useForce>
        <multiplier>-2500</multiplier>
        <offset>0</offset>
        <servo_min>1000</servo_min>
        <servo_max>2000</servo_max>
        <type>VELOCITY</type>
        <p_gain>0.50</p_gain>
        <cmd_max>20.0</cmd_max>
        <cmd_min>-20.0</cmd_min>
      </control>

      <control channel="5">
        <jointName>rotor_1_joint</jointName>
        <useForce>1</useForce>
        <multiplier>-2500</multiplier>
        <offset>0</offset>
        <servo_min>1000</servo_min>
        <servo_max>2000</servo_max>
        <type>VELOCITY</type>
        <p_gain>0.50</p_gain>
        <cmd_max>20.0</cmd_max>
        <cmd_min>-20.0</cmd_min>
      </control>

      <control channel="6">
        <jointName>rotor_2_joint</jointName>
        <useForce>1</useForce>
        <multiplier>2500</multiplier>
        <offset>0</offset>
        <servo_min>1000</servo_min>
        <servo_max>2000</servo_max>
        <type>VELOCITY</type>
        <p_gain>0.50</p_gain>
        <cmd_max>20.0</cmd_max>
        <cmd_min>-20.0</cmd_min>
      </control>

      <control channel="7">
        <jointName>rotor_3_joint</jointName>
        <useForce>1</useForce>
        <multiplier>2500</multiplier>
        <offset>0</offset>
        <servo_min>1000</servo_min>
        <servo_max>2000</servo_max>
        <type>VELOCITY</type>
        <p_gain>0.50</p_gain>
        <cmd_max>20.0</cmd_max>
        <cmd_min>-20.0</cmd_min>
      </control>
    </plugin>
  </model>
</sdf>
